Workbook

Sheet Raw_customers
A1: customer_id | B1: Customer_Country | C1: customer_name | D1: segment | E1: city | F1: country | G1: signup_date
A2: C0001 | B2: =IFERROR(INDEX(customers[country], MATCH(customers[[#This Row],[customer_id]], customers[customer_id], 0)), "Unmapped") -> Latvia | C2: House and Sons | D2: Consumer | E2: South Todd | F2: Latvia | G2: 44807
A3: C0002 | B3: =IFERROR(INDEX(customers[country], MATCH(customers[[#This Row],[customer_id]], customers[customer_id], 0)), "Unmapped") -> Sweden | C3: Barrera-Martin | D3: Consumer | E3: South Josephmouth | F3: Sweden | G3: 44935
A4: C0003 | B4: =IFERROR(INDEX(customers[country], MATCH(customers[[#This Row],[customer_id]], customers[customer_id], 0)), "Unmapped") -> Estonia | C4: Bernard, Cowan and Peters | D4: Consumer | E4: Mooreport | F4: Estonia | G4: 44814
A5: C0004 | B5: =IFERROR(INDEX(customers[country], MATCH(customers[[#This Row],[customer_id]], customers[customer_id], 0)), "Unmapped") -> Poland | C5: Noah Brown | D5: SME | E5: Brianshire | F5: Poland | G5: 45279
A6: C0005 | B6: =IFERROR(INDEX(customers[country], MATCH(customers[[#This Row],[customer_id]], customers[customer_id], 0)), "Unmapped") -> Sweden | C6: Moore, Yu and Miller | D6: SME | E6: North Brooke | F6: Sweden | G6: 45636
A7: C0006 | B7: =IFERROR(INDEX(customers[country], MATCH(customers[[#This Row],[customer_id]], customers[customer_id], 0)), "Unmapped") -> Latvia | C7: Powell PLC | D7: SME | E7: New Brooke | F7: Latvia | G7: 45536
A8: C0007 | B8: =IFERROR(INDEX(customers[country], MATCH(customers[[#This Row],[customer_id]], customers[customer_id], 0)), "Unmapped") -> Netherlands | C8: Sandoval-Cunningham | D8: SME | E8: Sarahborough | F8: Netherlands | G8: 45626
A9: C0008 | B9: =IFERROR(INDEX(customers[country], MATCH(customers[[#This Row],[customer_id]], customers[customer_id], 0)), "Unmapped") -> Sweden | C9: Allen-Foster | D9: Enterprise | E9: Stephenland | F9: Sweden | G9: 44439
A10: C0009 | B10: =IFERROR(INDEX(customers[country], MATCH(customers[[#This Row],[customer_id]], customers[customer_id], 0)), "Unmapped") -> Lithuania | C10: Murillo, Ferrell and Jones | D10: SME | E10: New Joseph | F10: Lithuania | G10: 46100
A11: C0010 | B11: =IFERROR(INDEX(customers[country], MATCH(customers[[#This Row],[customer_id]], customers[customer_id], 0)), "Unmapped") -> Estonia | C11: Suarez LLC | D11: Consumer | E11: Ericside | F11: Estonia | G11: 45687
A12: C0011 | B12: =IFERROR(INDEX(customers[country], MATCH(customers[[#This Row],[customer_id]], customers[customer_id], 0)), "Unmapped") -> Netherlands | C12: Riggs, Roman and Rice | D12: Consumer | E12: Sarahville | F12: Netherlands | G12: 46110
A13: C0012 | B13: =IFERROR(INDEX(customers[country], MATCH(customers[[#This Row],[customer_id]], customers[customer_id], 0)), "Unmapped") -> Poland | C13: Brian Rodriguez | D13: Consumer | E13: West Juan | F13: Poland | G13: 44801
... A301: C0300 | B301: =IFERROR(INDEX(customers[country], MATCH(customers[[#This Row],[customer_id]], customers[customer_id], 0)), "Unmapped") -> Poland | C301: Johnny Brown | D301: SME | E301: Hillport | F301: Poland | G301: 45293

Sheet Raw_shipments
A1: shipment_id | B1: order_id | C1: carrier | D1: ship_date | E1: scheduled_delivery_date | F1: actual_delivery_date | G1: shipping_cost_eur | H1: Delivery_Performance | I1: Region | J1: Cleaned_delivery_status | K1: delivery_status
A2: SHP0000001 | B2: ORD000104 | C2: UPS | D2: 45390 | E2: 45400 | F2: 45405 | G2: 57.47 | H2: =IF(shipments[[#This Row],[Cleaned_delivery_status]]="Cancelled", "Cancelled", IF(ISBLANK(shipments[[#This Row],[actual_delivery_date]]), "In Transit", IF(shipments[[#This Row],[actual_delivery_date]]<=shipments[[#This Row],[scheduled_delivery_date]], "On Time", "Late"))) -> Late | I2: =IFERROR(INDEX(Raw_orders!G:G, MATCH(shipments[[#This Row],[order_id]],Raw_orders!A:A, 0)), "Unknown") -> Nordics | J2: =PROPER(shipments[[#This Row],[delivery_status]]) -> Delivered | K2: Delivered
A3: SHP0000002 | B3: ORD000258 | C3: UPS | D3: 45275 | E3: 45282 | F3: 45289 | G3: 47.42 | H3: =IF(shipments[[#This Row],[Cleaned_delivery_status]]="Cancelled", "Cancelled", IF(ISBLANK(shipments[[#This Row],[actual_delivery_date]]), "In Transit", IF(shipments[[#This Row],[actual_delivery_date]]<=shipments[[#This Row],[scheduled_delivery_date]], "On Time", "Late"))) -> Late | I3: =IFERROR(INDEX(Raw_orders!G:G, MATCH(shipments[[#This Row],[order_id]],Raw_orders!A:A, 0)), "Unknown") -> Central Europe | J3: =PROPER(shipments[[#This Row],[delivery_status]]) -> Delivered | K3: Delivered
A4: SHP0000003 | B4: ORD003300 | C4: DPD | D4: 44993 | E4: 44996 | F4: 45006 | G4: 48.51 | H4: =IF(shipments[[#This Row],[Cleaned_delivery_status]]="Cancelled", "Cancelled", IF(ISBLANK(shipments[[#This Row],[actual_delivery_date]]), "In Transit", IF(shipments[[#This Row],[actual_delivery_date]]<=shipments[[#This Row],[scheduled_delivery_date]], "On Time", "Late"))) -> Late | I4: =IFERROR(INDEX(Raw_orders!G:G, MATCH(shipments[[#This Row],[order_id]],Raw_orders!A:A, 0)), "Unknown") -> Baltics | J4: =PROPER(shipments[[#This Row],[delivery_status]]) -> Delivered | K4: delivered | N4: Total Delivered | O4: On Time | P4: Late | Q4: Ontime delivery rate
A5: SHP0000004 | B5: ORD003057 | C5: DHL | D5: 45321 | E5: 45324 | F5: 45338 | G5: 53.15 | H5: =IF(shipments[[#This Row],[Cleaned_delivery_status]]="Cancelled", "Cancelled", IF(ISBLANK(shipments[[#This Row],[actual_delivery_date]]), "In Transit", IF(shipments[[#This Row],[actual_delivery_date]]<=shipments[[#This Row],[scheduled_delivery_date]], "On Time", "Late"))) -> Late | I5: =IFERROR(INDEX(Raw_orders!G:G, MATCH(shipments[[#This Row],[order_id]],Raw_orders!A:A, 0)), "Unknown") -> Nordics | J5: =PROPER(shipments[[#This Row],[delivery_status]]) -> Delivered | K5: DELIVERED | M5: DHL | N5: =COUNTIFS(C:C,"DHL",J:J,"Delivered") -> 670 | O5: =COUNTIFS(shipments[carrier], "DHL", shipments[Delivery_Performance], "On Time") -> 239 | P5: =COUNTIFS(shipments[carrier], "DHL", shipments[Delivery_Performance], "Late") -> 431 | Q5: =(O5/N5) -> 0.35671642
A6: SHP0000005 | B6: ORD000697 | C6: Matkahuolto | D6: 45239 | E6: 45246 | F6: 45246 | G6: 40.55 | H6: =IF(shipments[[#This Row],[Cleaned_delivery_status]]="Cancelled", "Cancelled", IF(ISBLANK(shipments[[#This Row],[actual_delivery_date]]), "In Transit", IF(shipments[[#This Row],[actual_delivery_date]]<=shipments[[#This Row],[scheduled_delivery_date]], "On Time", "Late"))) -> On Time | I6: =IFERROR(INDEX(Raw_orders!G:G, MATCH(shipments[[#This Row],[order_id]],Raw_orders!A:A, 0)), "Unknown") -> Baltics | J6: =PROPER(shipments[[#This Row],[delivery_status]]) -> Delivered | K6: delivered | M6: POSTNORD | N6: =COUNTIFS(C:C,"PostNord",J:J,"Delivered") -> 674 | O6: =COUNTIFS(shipments[carrier], "PostNord", shipments[Delivery_Performance], "On Time") -> 250 | P6: =COUNTIFS(shipments[carrier], "PostNord", shipments[Delivery_Performance], "Late") -> 424 | Q6: =(O6/N6) -> 0.37091988
A7: SHP0000006 | B7: ORD004047 | C7: UPS | D7: 45620 | E7: 45623 | F7: 45625 | G7: 58.52 | H7: =IF(shipments[[#This Row],[Cleaned_delivery_status]]="Cancelled", "Cancelled", IF(ISBLANK(shipments[[#This Row],[actual_delivery_date]]), "In Transit", IF(shipments[[#This Row],[actual_delivery_date]]<=shipments[[#This Row],[scheduled_delivery_date]], "On Time", "Late"))) -> Late | I7: =IFERROR(INDEX(Raw_orders!G:G, MATCH(shipments[[#This Row],[order_id]],Raw_orders!A:A, 0)), "Unknown") -> Nordics | J7: =PROPER(shipments[[#This Row],[delivery_status]]) -> Delivered | K7: delivered | M7: Matkahuolto | N7: =COUNTIFS(C:C,M7,J:J,"Delivered") -> 624 | O7: =COUNTIFS(shipments[carrier], M7, shipments[Delivery_Performance], "On Time") -> 226 | P7: =COUNTIFS(shipments[carrier], M7, shipments[Delivery_Performance], "Late") -> 398 | Q7: =(O7/N7) -> 0.36217949
A8: SHP0000007 | B8: ORD005666 | C8: UPS | D8: 45310 | E8: 45315 | F8: 45323 | G8: 25.11 | H8: =IF(shipments[[#This Row],[Cleaned_delivery_status]]="Cancelled", "Cancelled", IF(ISBLANK(shipments[[#This Row],[actual_delivery_date]]), "In Transit", IF(shipments[[#This Row],[actual_delivery_date]]<=shipments[[#This Row],[scheduled_delivery_date]], "On Time", "Late"))) -> Late | I8: =IFERROR(INDEX(Raw_orders!G:G, MATCH(shipments[[#This Row],[order_id]],Raw_orders!A:A, 0)), "Unknown") -> Nordics | J8: =PROPER(shipments[[#This Row],[delivery_status]]) -> Delivered | K8: delivered | M8: UPS | N8: =COUNTIFS(C:C,M8,J:J,"Delivered") -> 630 | O8: =COUNTIFS(shipments[carrier], M8, shipments[Delivery_Performance], "On Time") -> 219 | P8: =COUNTIFS(shipments[carrier], M8, shipments[Delivery_Performance], "Late") -> 411 | Q8: =(O8/N8) -> 0.34761905
A9: SHP0000008 | B9: ORD003739 | C9: PostNord | D9: 44986 | E9: 44991 | F9: 44990 | G9: 61.23 | H9: =IF(shipments[[#This Row],[Cleaned_delivery_status]]="Cancelled", "Cancelled", IF(ISBLANK(shipments[[#This Row],[actual_delivery_date]]), "In Transit", IF(shipments[[#This Row],[actual_delivery_date]]<=shipments[[#This Row],[scheduled_delivery_date]], "On Time", "Late"))) -> On Time | I9: =IFERROR(INDEX(Raw_orders!G:G, MATCH(shipments[[#This Row],[order_id]],Raw_orders!A:A, 0)), "Unknown") -> Central Europe | J9: =PROPER(shipments[[#This Row],[delivery_status]]) -> Delivered | K9: delivered | M9: Budbee | N9: =COUNTIFS(C:C,M9,J:J,"Delivered") -> 682 | O9: =COUNTIFS(shipments[carrier], M9, shipments[Delivery_Performance], "On Time") -> 266 | P9: =COUNTIFS(shipments[carrier], M9, shipments[Delivery_Performance], "Late") -> 416 | Q9: =(O9/N9) -> 0.39002933
A10: SHP0000009 | B10: ORD003779 | C10: PostNord | D10: 45006 | E10: 45013 | F10: 45013 | G10: 4.79 | H10: =IF(shipments[[#This Row],[Cleaned_delivery_status]]="Cancelled", "Cancelled", IF(ISBLANK(shipments[[#This Row],[actual_delivery_date]]), "In Transit", IF(shipments[[#This Row],[actual_delivery_date]]<=shipments[[#This Row],[scheduled_delivery_date]], "On Time", "Late"))) -> On Time | I10: =IFERROR(INDEX(Raw_orders!G:G, MATCH(shipments[[#This Row],[order_id]],Raw_orders!A:A, 0)), "Unknown") -> Baltics | J10: =PROPER(shipments[[#This Row],[delivery_status]]) -> Delivered | K10: delivered | M10: Bring | N10: =COUNTIFS(C:C,M10,J:J,"Delivered") -> 685 | O10: =COUNTIFS(shipments[carrier], M10, shipments[Delivery_Performance], "On Time") -> 257 | P10: =COUNTIFS(shipments[carrier], M10, shipments[Delivery_Performance], "Late") -> 428 | Q10: =(O10/N10) -> 0.37518248
A11: SHP0000010 | B11: ORD002570 | C11: Budbee | D11: 45542 | E11: 45547 | F11: 45555 | G11: 57.47 | H11: =IF(shipments[[#This Row],[Cleaned_delivery_status]]="Cancelled", "Cancelled", IF(ISBLANK(shipments[[#This Row],[actual_delivery_date]]), "In Transit", IF(shipments[[#This Row],[actual_delivery_date]]<=shipments[[#This Row],[scheduled_delivery_date]], "On Time", "Late"))) -> Late | I11: =IFERROR(INDEX(Raw_orders!G:G, MATCH(shipments[[#This Row],[order_id]],Raw_orders!A:A, 0)), "Unknown") -> Nordics | J11: =PROPER(shipments[[#This Row],[delivery_status]]) -> Delivered | K11: delivered | M11: DB Schenker | N11: =COUNTIFS(C:C,M11,J:J,"Delivered") -> 620 | O11: =COUNTIFS(shipments[carrier], M11, shipments[Delivery_Performance], "On Time") -> 220 | P11: =COUNTIFS(shipments[carrier], M11, shipments[Delivery_Performance], "Late") -> 400 | Q11: =(O11/N11) -> 0.35483871
A12: SHP0000011 | B12: ORD003191 | C12: Bring | D12: 45228 | E12: 45231 | F12: 45231 | G12: 27.82 | H12: =IF(shipments[[#This Row],[Cleaned_delivery_status]]="Cancelled", "Cancelled", IF(ISBLANK(shipments[[#This Row],[actual_delivery_date]]), "In Transit", IF(shipments[[#This Row],[actual_delivery_date]]<=shipments[[#This Row],[scheduled_delivery_date]], "On Time", "Late"))) -> On Time | I12: =IFERROR(INDEX(Raw_orders!G:G, MATCH(shipments[[#This Row],[order_id]],Raw_orders!A:A, 0)), "Unknown") -> Baltics | J12: =PROPER(shipments[[#This Row],[delivery_status]]) -> Delivered | K12: delivered | M12: DPD | N12: =COUNTIFS(C:C,M12,J:J,"Delivered") -> 662 | O12: =COUNTIFS(shipments[carrier], M12, shipments[Delivery_Performance], "On Time") -> 244 | P12: =COUNTIFS(shipments[carrier], M12, shipments[Delivery_Performance], "Late") -> 418 | Q12: =(O12/N12) -> 0.36858006
A13: SHP0000012 | B13: ORD002284 | C13: UPS | D13: 45509 | E13: 45514 | F13: 45522 | G13: 16.29 | H13: =IF(shipments[[#This Row],[Cleaned_delivery_status]]="Cancelled", "Cancelled", IF(ISBLANK(shipments[[#This Row],[actual_delivery_date]]), "In Transit", IF(shipments[[#This Row],[actual_delivery_date]]<=shipments[[#This Row],[scheduled_delivery_date]], "On Time", "Late"))) -> Late | I13: =IFERROR(INDEX(Raw_orders!G:G, MATCH(shipments[[#This Row],[order_id]],Raw_orders!A:A, 0)), "Unknown") -> Central Europe | J13: =PROPER(shipments[[#This Row],[delivery_status]]) -> Delivered | K13: DELIVERED
A14: SHP0000013 | B14: ORD004946 | C14: DPD | D14: 45343 | E14: 45348 | F14: 45359 | G14: 47.59 | H14: =IF(shipments[[#This Row],[Cleaned_delivery_status]]="Cancelled", "Cancelled", IF(ISBLANK(shipments[[#This Row],[actual_delivery_date]]), "In Transit", IF(shipments[[#This Row],[actual_delivery_date]]<=shipments[[#This Row],[scheduled_delivery_date]], "On Time", "Late"))) -> Late | I14: =IFERROR(INDEX(Raw_orders!G:G, MATCH(shipments[[#This Row],[order_id]],Raw_orders!A:A, 0)), "Unknown") -> Central Europe | J14: =PROPER(shipments[[#This Row],[delivery_status]]) -> Delivered | K14: delivered
A15: SHP0000014 | B15: ORD000875 | C15: Bring | D15: 45329 | E15: 45334 | F15: 45337 | G15: 7.71 | H15: =IF(shipments[[#This Row],[Cleaned_delivery_status]]="Cancelled", "Cancelled", IF(ISBLANK(shipments[[#This Row],[actual_delivery_date]]), "In Transit", IF(shipments[[#This Row],[actual_delivery_date]]<=shipments[[#This Row],[scheduled_delivery_date]], "On Time", "Late"))) -> Late | I15: =IFERROR(INDEX(Raw_orders!G:G, MATCH(shipments[[#This Row],[order_id]],Raw_orders!A:A, 0)), "Unknown") -> Nordics | J15: =PROPER(shipments[[#This Row],[delivery_status]]) -> Delivered | K15: Delivered | N15: Total Delivered | O15: On Time | P15: Late | Q15: Ontime delivery rate
A16: SHP0000015 | B16: ORD000802 | C16: DPD | D16: 45467 | E16: 45477 | F16: 45480 | G16: 45.08 | H16: =IF(shipments[[#This Row],[Cleaned_delivery_status]]="Cancelled", "Cancelled", IF(ISBLANK(shipments[[#This Row],[actual_delivery_date]]), "In Transit", IF(shipments[[#This Row],[actual_delivery_date]]<=shipments[[#This Row],[scheduled_delivery_date]], "On Time", "Late"))) -> Late | I16: =IFERROR(INDEX(Raw_orders!G:G, MATCH(shipments[[#This Row],[order_id]],Raw_orders!A:A, 0)), "Unknown") -> Central Europe | J16: =PROPER(shipments[[#This Row],[delivery_status]]) -> Delivered | K16: delivered | M16: Nordics | N16: =COUNTIFS(I:I,M16,J:J,"Delivered") -> 1777 | O16: =COUNTIFS(I:I, M16, H:H, "On Time") -> 662 | P16: =COUNTIFS(I:I,M16,H:H,P15) -> 1115 | Q16: =(O16/N16) -> 0.37253799
A17: SHP0000016 | B17: ORD005834 | C17: DHL | D17: 45235 | E17: 45242 | G17: 21.44 | H17: =IF(shipments[[#This Row],[Cleaned_delivery_status]]="Cancelled", "Cancelled", IF(ISBLANK(shipments[[#This Row],[actual_delivery_date]]), "In Transit", IF(shipments[[#This Row],[actual_delivery_date]]<=shipments[[#This Row],[scheduled_delivery_date]], "On Time", "Late"))) -> In Transit | I17: =IFERROR(INDEX(Raw_orders!G:G, MATCH(shipments[[#This Row],[order_id]],Raw_orders!A:A, 0)), "Unknown") -> Unknown | J17: =PROPER(shipments[[#This Row],[delivery_status]]) -> In Transit | K17: in transit | M17: Baltics | N17: =COUNTIFS(I:I,M17,J:J,"Delivered") -> 1690 | O17: =COUNTIFS(I:I, M17, H:H, "On Time") -> 616 | P17: =COUNTIFS(I:I,M17,H:H,P15) -> 1074 | Q17: =(O17/N17) -> 0.36449704
A18: SHP0000017 | B18: ORD000840 | C18: DPD | D18: 45314 | E18: 45316 | F18: 45321 | G18: 49.57 | H18: =IF(shipments[[#This Row],[Cleaned_delivery_status]]="Cancelled", "Cancelled", IF(ISBLANK(shipments[[#This Row],[actual_delivery_date]]), "In Transit", IF(shipments[[#This Row],[actual_delivery_date]]<=shipments[[#This Row],[scheduled_delivery_date]], "On Time", "Late"))) -> Late | I18: =IFERROR(INDEX(Raw_orders!G:G, MATCH(shipments[[#This Row],[order_id]],Raw_orders!A:A, 0)), "Unknown") -> Baltics | J18: =PROPER(shipments[[#This Row],[delivery_status]]) -> Delivered | K18: delivered | M18: Central Europe | N18: =COUNTIFS(I:I,M18,J:J,"Delivered") -> 1853 | O18: =COUNTIFS(I:I, M18, H:H, "On Time") -> 658 | P18: =COUNTIFS(I:I,M18,H:H,P15) -> 1195 | Q18: =(O18/N18) -> 0.35509984
A19: SHP0000018 | B19: ORD000004 | D19: 45588 | E19: 45595 | F19: 45594 | G19: 22.54 | H19: =IF(shipments[[#This Row],[Cleaned_delivery_status]]="Cancelled", "Cancelled", IF(ISBLANK(shipments[[#This Row],[actual_delivery_date]]), "In Transit", IF(shipments[[#This Row],[actual_delivery_date]]<=shipments[[#This Row],[scheduled_delivery_date]], "On Time", "Late"))) -> On Time | I19: =IFERROR(INDEX(Raw_orders!G:G, MATCH(shipments[[#This Row],[order_id]],Raw_orders!A:A, 0)), "Unknown") -> Central Europe | J19: =PROPER(shipments[[#This Row],[delivery_status]]) -> Delivered | K19: delivered
A20: SHP0000019 | B20: ORD005195 | C20: PostNord | D20: 45485 | E20: 45490 | G20: 46.55 | H20: =IF(shipments[[#This Row],[Cleaned_delivery_status]]="Cancelled", "Cancelled", IF(ISBLANK(shipments[[#This Row],[actual_delivery_date]]), "In Transit", IF(shipments[[#This Row],[actual_delivery_date]]<=shipments[[#This Row],[scheduled_delivery_date]], "On Time", "Late"))) -> In Transit | I20: =IFERROR(INDEX(Raw_orders!G:G, MATCH(shipments[[#This Row],[order_id]],Raw_orders!A:A, 0)), "Unknown") -> Nordics | J20: =PROPER(shipments[[#This Row],[delivery_status]]) -> In Transit | K20: in transit
A21: SHP0000020 | B21: ORD000910 | C21: PostNord | D21: 45298 | E21: 45301 | F21: 45302 | G21: 59.52 | H21: =IF(shipments[[#This Row],[Cleaned_delivery_status]]="Cancelled", "Cancelled", IF(ISBLANK(shipments[[#This Row],[actual_delivery_date]]), "In Transit", IF(shipments[[#This Row],[actual_delivery_date]]<=shipments[[#This Row],[scheduled_delivery_date]], "On Time", "Late"))) -> Late | I21: =IFERROR(INDEX(Raw_orders!G:G, MATCH(shipments[[#This Row],[order_id]],Raw_orders!A:A, 0)), "Unknown") -> Baltics | J21: =PROPER(shipments[[#This Row],[delivery_status]]) -> Delivered | K21: Delivered
A22: SHP0000021 | B22: ORD000910 | C22: Budbee | D22: 45296 | E22: 45306 | F22: 45308 | G22: 58.19 | H22: =IF(shipments[[#This Row],[Cleaned_delivery_status]]="Cancelled", "Cancelled", IF(ISBLANK(shipments[[#This Row],[actual_delivery_date]]), "In Transit", IF(shipments[[#This Row],[actual_delivery_date]]<=shipments[[#This Row],[scheduled_delivery_date]], "On Time", "Late"))) -> Late | I22: =IFERROR(INDEX(Raw_orders!G:G, MATCH(shipments[[#This Row],[order_id]],Raw_orders!A:A, 0)), "Unknown") -> Baltics | J22: =PROPER(shipments[[#This Row],[delivery_status]]) -> Delivered | K22: Delivered | M22: Total Delivered Orders | N22: =COUNTIF(shipments[Cleaned_delivery_status], "Delivered") -> 5406
A23: SHP0000022 | B23: ORD005909 | C23: Budbee | D23: 45246 | E23: 45249 | F23: 45259 | G23: 42.31 | H23: =IF(shipments[[#This Row],[Cleaned_delivery_status]]="Cancelled", "Cancelled", IF(ISBLANK(shipments[[#This Row],[actual_delivery_date]]), "In Transit", IF(shipments[[#This Row],[actual_delivery_date]]<=shipments[[#This Row],[scheduled_delivery_date]], "On Time", "Late"))) -> Late | I23: =IFERROR(INDEX(Raw_orders!G:G, MATCH(shipments[[#This Row],[order_id]],Raw_orders!A:A, 0)), "Unknown") -> Baltics | J23: =PROPER(shipments[[#This Row],[delivery_status]]) -> Delivered | K23: DELIVERED | M23: Overall Network On-Time Rate (%) | N23: =COUNTIFS(shipments[Cleaned_delivery_status], "Delivered", shipments[Delivery_Performance], "On Time") / COUNTIF(shipments[Cleaned_delivery_status], "Delivered") -> 0.36570477
A24: SHP0000023 | B24: ORD004418 | C24: PostNord | D24: 45097 | E24: 45102 | G24: 6.01 | H24: =IF(shipments[[#This Row],[Cleaned_delivery_status]]="Cancelled", "Cancelled", IF(ISBLANK(shipments[[#This Row],[actual_delivery_date]]), "In Transit", IF(shipments[[#This Row],[actual_delivery_date]]<=shipments[[#This Row],[scheduled_delivery_date]], "On Time", "Late"))) -> In Transit | I24: =IFERROR(INDEX(Raw_orders!G:G, MATCH(shipments[[#This Row],[order_id]],Raw_orders!A:A, 0)), "Unknown") -> Nordics | J24: =PROPER(shipments[[#This Row],[delivery_status]]) -> In Transit | K24: in transit | M24: Total Shipping Cost (€) | N24: =SUM(G:G) -> 217738.12
A25: SHP0000024 | B25: ORD000563 | C25: DB Schenker | D25: 45038 | E25: 45041 | F25: 45042 | G25: 10.22 | H25: =IF(shipments[[#This Row],[Cleaned_delivery_status]]="Cancelled", "Cancelled", IF(ISBLANK(shipments[[#This Row],[actual_delivery_date]]), "In Transit", IF(shipments[[#This Row],[actual_delivery_date]]<=shipments[[#This Row],[scheduled_delivery_date]], "On Time", "Late"))) -> Late | I25: =IFERROR(INDEX(Raw_orders!G:G, MATCH(shipments[[#This Row],[order_id]],Raw_orders!A:A, 0)), "Unknown") -> Nordics | J25: =PROPER(shipments[[#This Row],[delivery_status]]) -> Delivered | K25: DELIVERED
A26: SHP0000025 | B26: ORD000289 | C26: PostNord | D26: 45033 | E26: 45043 | G26: 15.78 | H26: =IF(shipments[[#This Row],[Cleaned_delivery_status]]="Cancelled", "Cancelled", IF(ISBLANK(shipments[[#This Row],[actual_delivery_date]]), "In Transit", IF(shipments[[#This Row],[actual_delivery_date]]<=shipments[[#This Row],[scheduled_delivery_date]], "On Time", "Late"))) -> In Transit | I26: =IFERROR(INDEX(Raw_orders!G:G, MATCH(shipments[[#This Row],[order_id]],Raw_orders!A:A, 0)), "Unknown") -> Nordics | J26: =PROPER(shipments[[#This Row],[delivery_status]]) -> In Transit | K26: IN TRANSIT
A27: SHP0000026 | B27: ORD005641 | C27: Bring | D27: 45348 | E27: 45355 | F27: 45356 | G27: 10.75 | H27: =IF(shipments[[#This Row],[Cleaned_delivery_status]]="Cancelled", "Cancelled", IF(ISBLANK(shipments[[#This Row],[actual_delivery_date]]), "In Transit", IF(shipments[[#This Row],[actual_delivery_date]]<=shipments[[#This Row],[scheduled_delivery_date]], "On Time", "Late"))) -> Late | I27: =IFERROR(INDEX(Raw_orders!G:G, MATCH(shipments[[#This Row],[order_id]],Raw_orders!A:A, 0)), "Unknown") -> Central Europe | J27: =PROPER(shipments[[#This Row],[delivery_status]]) -> Delivered | K27: delivered
A28: SHP0000027 | B28: ORD005650 | D28: 45042 | E28: 45052 | F28: 45052 | G28: 51.79 | H28: =IF(shipments[[#This Row],[Cleaned_delivery_status]]="Cancelled", "Cancelled", IF(ISBLANK(shipments[[#This Row],[actual_delivery_date]]), "In Transit", IF(shipments[[#This Row],[actual_delivery_date]]<=shipments[[#This Row],[scheduled_delivery_date]], "On Time", "Late"))) -> On Time | I28: =IFERROR(INDEX(Raw_orders!G:G, MATCH(shipments[[#This Row],[order_id]],Raw_orders!A:A, 0)), "Unknown") -> Nordics | J28: =PROPER(shipments[[#This Row],[delivery_status]]) -> Delivered | K28: DELIVERED
A29: SHP0000028 | B29: ORD005650 | C29: Bring | D29: 45043 | E29: 45046 | F29: 45049 | G29: 58.78 | H29: =IF(shipments[[#This Row],[Cleaned_delivery_status]]="Cancelled", "Cancelled", IF(ISBLANK(shipments[[#This Row],[actual_delivery_date]]), "In Transit", IF(shipments[[#This Row],[actual_delivery_date]]<=shipments[[#This Row],[scheduled_delivery_date]], "On Time", "Late"))) -> Late | I29: =IFERROR(INDEX(Raw_orders!G:G, MATCH(shipments[[#This Row],[order_id]],Raw_orders!A:A, 0)), "Unknown") -> Nordics | J29: =PROPER(shipments[[#This Row],[delivery_status]]) -> Delivered | K29: Delivered | M29: Carrier | N29: On Time | Q29: Ontime delivery rate
A30: SHP0000029 | B30: ORD003814 | C30: Budbee | D30: 44987 | E30: 44994 | G30: 34.6 | H30: =IF(shipments[[#This Row],[Cleaned_delivery_status]]="Cancelled", "Cancelled", IF(ISBLANK(shipments[[#This Row],[actual_delivery_date]]), "In Transit", IF(shipments[[#This Row],[actual_delivery_date]]<=shipments[[#This Row],[scheduled_delivery_date]], "On Time", "Late"))) -> Cancelled | I30: =IFERROR(INDEX(Raw_orders!G:G, MATCH(shipments[[#This Row],[order_id]],Raw_orders!A:A, 0)), "Unknown") -> Central Europe | J30: =PROPER(shipments[[#This Row],[delivery_status]]) -> Cancelled | K30: Cancelled | M30: DHL | N30: 0.35671642 | P30: Nordics | Q30: 0.37253799
A31: SHP0000030 | B31: ORD003176 | C31: Matkahuolto | D31: 45239 | E31: 45246 | F31: 45249 | G31: 57.71 | H31: =IF(shipments[[#This Row],[Cleaned_delivery_status]]="Cancelled", "Cancelled", IF(ISBLANK(shipments[[#This Row],[actual_delivery_date]]), "In Transit", IF(shipments[[#This Row],[actual_delivery_date]]<=shipments[[#This Row],[scheduled_delivery_date]], "On Time", "Late"))) -> Late | I31: =IFERROR(INDEX(Raw_orders!G:G, MATCH(shipments[[#This Row],[order_id]],Raw_orders!A:A, 0)), "Unknown") -> Baltics | J31: =PROPER(shipments[[#This Row],[delivery_status]]) -> Delivered | K31: Delivered | M31: POSTNORD | N31: 0.37091988 | P31: Baltics | Q31: 0.36449704
A32: SHP0000031 | B32: ORD002824 | C32: Budbee | D32: 44982 | E32: 44989 | F32: 44991 | G32: 28.78 | H32: =IF(shipments[[#This Row],[Cleaned_delivery_status]]="Cancelled", "Cancelled", IF(ISBLANK(shipments[[#This Row],[actual_delivery_date]]), "In Transit", IF(shipments[[#This Row],[actual_delivery_date]]<=shipments[[#This Row],[scheduled_delivery_date]], "On Time", "Late"))) -> Late | I32: =IFERROR(INDEX(Raw_orders!G:G, MATCH(shipments[[#This Row],[order_id]],Raw_orders!A:A, 0)), "Unknown") -> Central Europe | J32: =PROPER(shipments[[#This Row],[delivery_status]]) -> Delivered | K32: Delivered | M32: Matkahuolto | N32: 0.36217949 | P32: Central Europe | Q32: 0.35509984
A33: SHP0000032 | B33: ORD002314 | C33: Bring | D33: 45204 | E33: 45206 | F33: 45216 | G33: 26.25 | H33: =IF(shipments[[#This Row],[Cleaned_delivery_status]]="Cancelled", "Cancelled", IF(ISBLANK(shipments[[#This Row],[actual_delivery_date]]), "In Transit", IF(shipments[[#This Row],[actual_delivery_date]]<=shipments[[#This Row],[scheduled_delivery_date]], "On Time", "Late"))) -> Late | I33: =IFERROR(INDEX(Raw_orders!G:G, MATCH(shipments[[#This Row],[order_id]],Raw_orders!A:A, 0)), "Unknown") -> Central Europe | J33: =PROPER(shipments[[#This Row],[delivery_status]]) -> Delivered | K33: delivered | M33: UPS | N33: 0.34761905
A34: SHP0000033 | B34: ORD003871 | C34: UPS | D34: 44963 | E34: 44970 | F34: 44978 | G34: 6.72 | H34: =IF(shipments[[#This Row],[Cleaned_delivery_status]]="Cancelled", "Cancelled", IF(ISBLANK(shipments[[#This Row],[actual_delivery_date]]), "In Transit", IF(shipments[[#This Row],[actual_delivery_date]]<=shipments[[#This Row],[scheduled_delivery_date]], "On Time", "Late"))) -> Late | I34: =IFERROR(INDEX(Raw_orders!G:G, MATCH(shipments[[#This Row],[order_id]],Raw_orders!A:A, 0)), "Unknown") -> Central Europe | J34: =PROPER(shipments[[#This Row],[delivery_status]]) -> Delivered | K34: delivered | M34: Budbee | N34: 0.39002933
A35: SHP0000034 | B35: ORD000815 | C35: UPS | D35: 45162 | E35: 45172 | F35: 45172 | G35: 26.4 | H35: =IF(shipments[[#This Row],[Cleaned_delivery_status]]="Cancelled", "Cancelled", IF(ISBLANK(shipments[[#This Row],[actual_delivery_date]]), "In Transit", IF(shipments[[#This Row],[actual_delivery_date]]<=shipments[[#This Row],[scheduled_delivery_date]], "On Time", "Late"))) -> On Time | I35: =IFERROR(INDEX(Raw_orders!G:G, MATCH(shipments[[#This Row],[order_id]],Raw_orders!A:A, 0)), "Unknown") -> Baltics | J35: =PROPER(shipments[[#This Row],[delivery_status]]) -> Delivered | K35: delivered | M35: Bring | N35: 0.37518248
A36: SHP0000035 | B36: ORD001126 | C36: Budbee | D36: 45070 | E36: 45072 | G36: 17.93 | H36: =IF(shipments[[#This Row],[Cleaned_delivery_status]]="Cancelled", "Cancelled", IF(ISBLANK(shipments[[#This Row],[actual_delivery_date]]), "In Transit", IF(shipments[[#This Row],[actual_delivery_date]]<=shipments[[#This Row],[scheduled_delivery_date]], "On Time", "Late"))) -> Cancelled | I36: =IFERROR(INDEX(Raw_orders!G:G, MATCH(shipments[[#This Row],[order_id]],Raw_orders!A:A, 0)), "Unknown") -> Baltics | J36: =PROPER(shipments[[#This Row],[delivery_status]]) -> Cancelled | K36: Cancelled | M36: DB Schenker | N36: 0.35483871
A37: SHP0000036 | B37: ORD002483 | C37: UPS | D37: 45144 | E37: 45151 | F37: 45154 | G37: 41.16 | H37: =IF(shipments[[#This Row],[Cleaned_delivery_status]]="Cancelled", "Cancelled", IF(ISBLANK(shipments[[#This Row],[actual_delivery_date]]), "In Transit", IF(shipments[[#This Row],[actual_delivery_date]]<=shipments[[#This Row],[scheduled_delivery_date]], "On Time", "Late"))) -> Late | I37: =IFERROR(INDEX(Raw_orders!G:G, MATCH(shipments[[#This Row],[order_id]],Raw_orders!A:A, 0)), "Unknown") -> Unknown | J37: =PROPER(shipments[[#This Row],[delivery_status]]) -> Delivered | K37: Delivered | M37: DPD | N37: 0.36858006
A38: SHP0000037 | B38: ORD002449 | C38: UPS | D38: 45460 | E38: 45462 | G38: 35.3 | H38: =IF(shipments[[#This Row],[Cleaned_delivery_status]]="Cancelled", "Cancelled", IF(ISBLANK(shipments[[#This Row],[actual_delivery_date]]), "In Transit", IF(shipments[[#This Row],[actual_delivery_date]]<=shipments[[#This Row],[scheduled_delivery_date]], "On Time", "Late"))) -> Cancelled | I38: =IFERROR(INDEX(Raw_orders!G:G, MATCH(shipments[[#This Row],[order_id]],Raw_orders!A:A, 0)), "Unknown") -> Baltics | J38: =PROPER(shipments[[#This Row],[delivery_status]]) -> Cancelled | K38: CANCELLED
A39: SHP0000038 | B39: ORD004155 | C39: UPS | D39: 45150 | E39: 45155 | F39: 45155 | G39: 4.72 | H39: =IF(shipments[[#This Row],[Cleaned_delivery_status]]="Cancelled", "Cancelled", IF(ISBLANK(shipments[[#This Row],[actual_delivery_date]]), "In Transit", IF(shipments[[#This Row],[actual_delivery_date]]<=shipments[[#This Row],[scheduled_delivery_date]], "On Time", "Late"))) -> On Time | I39: =IFERROR(INDEX(Raw_orders!G:G, MATCH(shipments[[#This Row],[order_id]],Raw_orders!A:A, 0)), "Unknown") -> Central Europe | J39: =PROPER(shipments[[#This Row],[delivery_status]]) -> Delivered | K39: DELIVERED
A40: SHP0000039 | B40: ORD005273 | C40: DHL | D40: 45215 | E40: 45218 | F40: 45218 | G40: 18.31 | H40: =IF(shipments[[#This Row],[Cleaned_delivery_status]]="Cancelled", "Cancelled", IF(ISBLANK(shipments[[#This Row],[actual_delivery_date]]), "In Transit", IF(shipments[[#This Row],[actual_delivery_date]]<=shipments[[#This Row],[scheduled_delivery_date]], "On Time", "Late"))) -> On Time | I40: =IFERROR(INDEX(Raw_orders!G:G, MATCH(shipments[[#This Row],[order_id]],Raw_orders!A:A, 0)), "Unknown") -> Baltics | J40: =PROPER(shipments[[#This Row],[delivery_status]]) -> Delivered | K40: DELIVERED
...

Sheet Raw_orders
A1: order_id | B1: customer_id | C1: order_date | D1: Clean_Order_Priority | E1: order_priority | F1: Customer_Country | G1: Derived_Region | H1: region
A2: ORD000104 | B2: C0275 | C2: 45387 | D2: =PROPER(orders[[#This Row],[order_priority]]) -> Economy | E2: Economy | F2: =IFERROR(INDEX(customers[country], MATCH(orders[[#This Row],[customer_id]], customers[customer_id], 0)), "Unmapped") -> Denmark | G2: =IFERROR(INDEX(Region_Map[Region], MATCH(orders[[#This Row],[Customer_Country]], Region_Map[Country], 0)), "Unknown") -> Nordics
A3: ORD000258 | B3: C0236 | C3: 45274 | D3: =PROPER(orders[[#This Row],[order_priority]]) -> Standard | E3: Standard | F3: =IFERROR(INDEX(customers[country], MATCH(orders[[#This Row],[customer_id]], customers[customer_id], 0)), "Unmapped") -> Netherlands | G3: =IFERROR(INDEX(Region_Map[Region], MATCH(orders[[#This Row],[Customer_Country]], Region_Map[Country], 0)), "Unknown") -> Central Europe
A4: ORD003300 | B4: C0068 | C4: 44991 | D4: =PROPER(orders[[#This Row],[order_priority]]) -> Express | E4: Express | F4: =IFERROR(INDEX(customers[country], MATCH(orders[[#This Row],[customer_id]], customers[customer_id], 0)), "Unmapped") -> Latvia | G4: =IFERROR(INDEX(Region_Map[Region], MATCH(orders[[#This Row],[Customer_Country]], Region_Map[Country], 0)), "Unknown") -> Baltics
A5: ORD003057 | B5: C0146 | C5: 45321 | D5: =PROPER(orders[[#This Row],[order_priority]]) -> Express | E5: Express | F5: =IFERROR(INDEX(customers[country], MATCH(orders[[#This Row],[customer_id]], customers[customer_id], 0)), "Unmapped") -> Sweden | G5: =IFERROR(INDEX(Region_Map[Region], MATCH(orders[[#This Row],[Customer_Country]], Region_Map[Country], 0)), "Unknown") -> Nordics
A6: ORD000697 | B6: C0104 | C6: 45237 | D6: =PROPER(orders[[#This Row],[order_priority]]) -> Economy | E6: Economy | F6: =IFERROR(INDEX(customers[country], MATCH(orders[[#This Row],[customer_id]], customers[customer_id], 0)), "Unmapped") -> Lithuania | G6: =IFERROR(INDEX(Region_Map[Region], MATCH(orders[[#This Row],[Customer_Country]], Region_Map[Country], 0)), "Unknown") -> Baltics
A7: ORD004047 | B7: C0181 | C7: 45618 | D7: =PROPER(orders[[#This Row],[order_priority]]) -> Standard | E7: standard | F7: =IFERROR(INDEX(customers[country], MATCH(orders[[#This Row],[customer_id]], customers[customer_id], 0)), "Unmapped") -> Norway | G7: =IFERROR(INDEX(Region_Map[Region], MATCH(orders[[#This Row],[Customer_Country]], Region_Map[Country], 0)), "Unknown") -> Nordics
A8: ORD005666 | B8: C0111 | C8: 45308 | D8: =PROPER(orders[[#This Row],[order_priority]]) -> Economy | E8: Economy | F8: =IFERROR(INDEX(customers[country], MATCH(orders[[#This Row],[customer_id]], customers[customer_id], 0)), "Unmapped") -> Norway | G8: =IFERROR(INDEX(Region_Map[Region], MATCH(orders[[#This Row],[Customer_Country]], Region_Map[Country], 0)), "Unknown") -> Nordics
A9: ORD003739 | B9: C0091 | C9: 44983 | D9: =PROPER(orders[[#This Row],[order_priority]]) -> Express | E9: Express | F9: =IFERROR(INDEX(customers[country], MATCH(orders[[#This Row],[customer_id]], customers[customer_id], 0)), "Unmapped") -> Netherlands | G9: =IFERROR(INDEX(Region_Map[Region], MATCH(orders[[#This Row],[Customer_Country]], Region_Map[Country], 0)), "Unknown") -> Central Europe
A10: ORD003779 | B10: C0239 | C10: 45003 | D10: =PROPER(orders[[#This Row],[order_priority]]) -> Standard | E10: Standard | F10: =IFERROR(INDEX(customers[country], MATCH(orders[[#This Row],[customer_id]], customers[customer_id], 0)), "Unmapped") -> Lithuania | G10: =IFERROR(INDEX(Region_Map[Region], MATCH(orders[[#This Row],[Customer_Country]], Region_Map[Country], 0)), "Unknown") -> Baltics
A11: ORD002570 | B11: C0026 | C11: 45541 | D11: =PROPER(orders[[#This Row],[order_priority]]) -> Express | E11: EXPRESS | F11: =IFERROR(INDEX(customers[country], MATCH(orders[[#This Row],[customer_id]], customers[customer_id], 0)), "Unmapped") -> Norway | G11: =IFERROR(INDEX(Region_Map[Region], MATCH(orders[[#This Row],[Customer_Country]], Region_Map[Country], 0)), "Unknown") -> Nordics
A12: ORD003191 | B12: C0270 | C12: 45227 | D12: =PROPER(orders[[#This Row],[order_priority]]) -> Express | E12: Express | F12: =IFERROR(INDEX(customers[country], MATCH(orders[[#This Row],[customer_id]], customers[customer_id], 0)), "Unmapped") -> Estonia | G12: =IFERROR(INDEX(Region_Map[Region], MATCH(orders[[#This Row],[Customer_Country]], Region_Map[Country], 0)), "Unknown") -> Baltics
A13: ORD002284 | B13: C0119 | C13: 45509 | D13: =PROPER(orders[[#This Row],[order_priority]]) -> Standard | E13: Standard | F13: =IFERROR(INDEX(customers[country], MATCH(orders[[#This Row],[customer_id]], customers[customer_id], 0)), "Unmapped") -> Germany | G13: =IFERROR(INDEX(Region_Map[Region], MATCH(orders[[#This Row],[Customer_Country]], Region_Map[Country], 0)), "Unknown") -> Central Europe
... A16: ORD000802 | B16: C0007 | C16: 45466 | D16: =PROPER(orders[[#This Row],[order_priority]]) -> Standard | E16: standard | F16: =IFERROR(INDEX(customers[country], MATCH(orders[[#This Row],[customer_id]], customers[customer_id], 0)), "Unmapped") -> Netherlands | G16: =IFERROR(INDEX(Region_Map[Region], MATCH(orders[[#This Row],[Customer_Country]], Region_Map[Country], 0)), "Unknown") -> Central Europe
A17: ORD005834 | C17: 45233 | D17: =PROPER(orders[[#This Row],[order_priority]]) -> Same Day | E17: same day | F17: =IFERROR(INDEX(customers[country], MATCH(orders[[#This Row],[customer_id]], customers[customer_id], 0)), "Unmapped") -> Unmapped | G17: =IFERROR(INDEX(Region_Map[Region], MATCH(orders[[#This Row],[Customer_Country]], Region_Map[Country], 0)), "Unknown") -> Unknown
A18: ORD000840 | B18: C0038 | C18: 45311 | D18: =PROPER(orders[[#This Row],[order_priority]]) -> Express | E18: Express | F18: =IFERROR(INDEX(customers[country], MATCH(orders[[#This Row],[customer_id]], customers[customer_id], 0)), "Unmapped") -> Latvia | G18: =IFERROR(INDEX(Region_Map[Region], MATCH(orders[[#This Row],[Customer_Country]], Region_Map[Country], 0)), "Unknown") -> Baltics
A19: ORD000004 | B19: C0196 | C19: 45588 | D19: =PROPER(orders[[#This Row],[order_priority]]) -> Same Day | E19: Same Day | F19: =IFERROR(INDEX(customers[country], MATCH(orders[[#This Row],[customer_id]], customers[customer_id], 0)), "Unmapped") -> Poland | G19: =IFERROR(INDEX(Region_Map[Region], MATCH(orders[[#This Row],[Customer_Country]], Region_Map[Country], 0)), "Unknown") -> Central Europe
A20: ORD005195 | B20: C0204 | C20: 45485 | D20: =PROPER(orders[[#This Row],[order_priority]]) -> Same Day | E20: Same Day | F20: =IFERROR(INDEX(customers[country], MATCH(orders[[#This Row],[customer_id]], customers[customer_id], 0)), "Unmapped") -> Denmark | G20: =IFERROR(INDEX(Region_Map[Region], MATCH(orders[[#This Row],[Customer_Country]], Region_Map[Country], 0)), "Unknown") -> Nordics
A21: ORD000910 | B21: C0194 | C21: 45295 | D21: =PROPER(orders[[#This Row],[order_priority]]) -> Standard | E21: Standard | F21: =IFERROR(INDEX(customers[country], MATCH(orders[[#This Row],[customer_id]], customers[customer_id], 0)), "Unmapped") -> Lithuania | G21: =IFERROR(INDEX(Region_Map[Region], MATCH(orders[[#This Row],[Customer_Country]], Region_Map[Country], 0)), "Unknown") -> Baltics
A22: ORD005909 | B22: C0135 | C22: 45244 | D22: =PROPER(orders[[#This Row],[order_priority]]) -> Express | E22: Express | F22: =IFERROR(INDEX(customers[country], MATCH(orders[[#This Row],[customer_id]], customers[customer_id], 0)), "Unmapped") -> Estonia | G22: =IFERROR(INDEX(Region_Map[Region], MATCH(orders[[#This Row],[Customer_Country]], Region_Map[Country], 0)), "Unknown") -> Baltics
A23: ORD004418 | B23: C0137 | C23: 45094 | D23: =PROPER(orders[[#This Row],[order_priority]]) -> Same Day | E23: Same Day | F23: =IFERROR(INDEX(customers[country], MATCH(orders[[#This Row],[customer_id]], customers[customer_id], 0)), "Unmapped") -> Denmark | G23: =IFERROR(INDEX(Region_Map[Region], MATCH(orders[[#This Row],[Customer_Country]], Region_Map[Country], 0)), "Unknown") -> Nordics
A24: ORD000563 | B24: C0203 | C24: 45035 | D24: =PROPER(orders[[#This Row],[order_priority]]) -> Standard | E24: STANDARD | F24: =IFERROR(INDEX(customers[country], MATCH(orders[[#This Row],[customer_id]], customers[customer_id], 0)), "Unmapped") -> Denmark | G24: =IFERROR(INDEX(Region_Map[Region], MATCH(orders[[#This Row],[Customer_Country]], Region_Map[Country], 0)), "Unknown") -> Nordics
A25: ORD000289 | B25: C0225 | C25: 45031 | D25: =PROPER(orders[[#This Row],[order_priority]]) -> Standard | E25: Standard | F25: =IFERROR(INDEX(customers[country], MATCH(orders[[#This Row],[customer_id]], customers[customer_id], 0)), "Unmapped") -> Norway | G25: =IFERROR(INDEX(Region_Map[Region], MATCH(orders[[#This Row],[Customer_Country]], Region_Map[Country], 0)), "Unknown") -> Nordics
A26: ORD005641 | B26: C0174 | C26: 45346 | D26: =PROPER(orders[[#This Row],[order_priority]]) -> Express | E26: Express | F26: =IFERROR(INDEX(customers[country], MATCH(orders[[#This Row],[customer_id]], customers[customer_id], 0)), "Unmapped") -> Germany | G26: =IFERROR(INDEX(Region_Map[Region], MATCH(orders[[#This Row],[Customer_Country]], Region_Map[Country], 0)), "Unknown") -> Central Europe
A27: ORD005650 | B27: C0268 | C27: 45041 | D27: =PROPER(orders[[#This Row],[order_priority]]) -> Same Day | E27: Same Day | F27: =IFERROR(INDEX(customers[country], MATCH(orders[[#This Row],[customer_id]], customers[customer_id], 0)), "Unmapped") -> Norway | G27: =IFERROR(INDEX(Region_Map[Region], MATCH(orders[[#This Row],[Customer_Country]], Region_Map[Country], 0)), "Unknown") -> Nordics
A28: ORD003814 | B28: C0223 | C28: 44984 | D28: =PROPER(orders[[#This Row],[order_priority]]) -> Standard | E28: Standard | F28: =IFERROR(INDEX(customers[country], MATCH(orders[[#This Row],[customer_id]], customers[customer_id], 0)), "Unmapped") -> Germany | G28: =IFERROR(INDEX(Region_Map[Region], MATCH(orders[[#This Row],[Customer_Country]], Region_Map[Country], 0)), "Unknown") -> Central Europe
A29: ORD003176 | B29: C0270 | C29: 45239 | D29: =PROPER(orders[[#This Row],[order_priority]]) -> Standard | E29: Standard | F29: =IFERROR(INDEX(customers[country], MATCH(orders[[#This Row],[customer_id]], customers[customer_id], 0)), "Unmapped") -> Estonia | G29: =IFERROR(INDEX(Region_Map[Region], MATCH(orders[[#This Row],[Customer_Country]], Region_Map[Country], 0)), "Unknown") -> Baltics
... A34: ORD001126 | B34: C0010 | C34: 45070 | D34: =PROPER(orders[[#This Row],[order_priority]]) -> Express | E34: Express | F34: =IFERROR(INDEX(customers[country], MATCH(orders[[#This Row],[customer_id]], customers[customer_id], 0)), "Unmapped") -> Estonia | G34: =IFERROR(INDEX(Region_Map[Region], MATCH(orders[[#This Row],[Customer_Country]], Region_Map[Country], 0)), "Unknown") -> Baltics
A35: ORD002483 | C35: 45144 | D35: =PROPER(orders[[#This Row],[order_priority]]) -> Standard | E35: Standard | F35: =IFERROR(INDEX(customers[country], MATCH(orders[[#This Row],[customer_id]], customers[customer_id], 0)), "Unmapped") -> Unmapped | G35: =IFERROR(INDEX(Region_Map[Region], MATCH(orders[[#This Row],[Customer_Country]], Region_Map[Country], 0)), "Unknown") -> Unknown
A36: ORD002449 | B36: C0149 | C36: 45460 | D36: =PROPER(orders[[#This Row],[order_priority]]) -> Standard | E36: Standard | F36: =IFERROR(INDEX(customers[country], MATCH(orders[[#This Row],[customer_id]], customers[customer_id], 0)), "Unmapped") -> Latvia | G36: =IFERROR(INDEX(Region_Map[Region], MATCH(orders[[#This Row],[Customer_Country]], Region_Map[Country], 0)), "Unknown") -> Baltics
A37: ORD004155 | B37: C0085 | C37: 45149 | D37: =PROPER(orders[[#This Row],[order_priority]]) -> Economy | E37: Economy | F37: =IFERROR(INDEX(customers[country], MATCH(orders[[#This Row],[customer_id]], customers[customer_id], 0)), "Unmapped") -> Poland | G37: =IFERROR(INDEX(Region_Map[Region], MATCH(orders[[#This Row],[Customer_Country]], Region_Map[Country], 0)), "Unknown") -> Central Europe
A38: ORD005273 | B38: C0226 | C38: 45215 | D38: =PROPER(orders[[#This Row],[order_priority]]) -> Express | E38: Express | F38: =IFERROR(INDEX(customers[country], MATCH(orders[[#This Row],[customer_id]], customers[customer_id], 0)), "Unmapped") -> Latvia | G38: =IFERROR(INDEX(Region_Map[Region], MATCH(orders[[#This Row],[Customer_Country]], Region_Map[Country], 0)), "Unknown") -> Baltics
A39: ORD001381 | B39: C0096 | C39: 45304 | D39: =PROPER(orders[[#This Row],[order_priority]]) -> Express | E39: Express | F39: =IFERROR(INDEX(customers[country], MATCH(orders[[#This Row],[customer_id]], customers[customer_id], 0)), "Unmapped") -> Netherlands | G39: =IFERROR(INDEX(Region_Map[Region], MATCH(orders[[#This Row],[Customer_Country]], Region_Map[Country], 0)), "Unknown") -> Central Europe
A40: ORD004066 | B40: C0267 | C40: 45390 | D40: =PROPER(orders[[#This Row],[order_priority]]) -> Same Day | E40: Same Day | F40: =IFERROR(INDEX(customers[country], MATCH(orders[[#This Row],[customer_id]], customers[customer_id], 0)), "Unmapped") -> Finland | G40: =IFERROR(INDEX(Region_Map[Region], MATCH(orders[[#This Row],[Customer_Country]], Region_Map[Country], 0)), "Unknown") -> Nordics
A41: ORD004746 | B41: C0233 | C41: 45024 | D41: =PROPER(orders[[#This Row],[order_priority]]) -> Same Day | E41: Same Day | F41: =IFERROR(INDEX(customers[country], MATCH(orders[[#This Row],[customer_id]], customers[customer_id], 0)), "Unmapped") -> Finland | G41: =IFERROR(INDEX(Region_Map[Region], MATCH(orders[[#This Row],[Customer_Country]], Region_Map[Country], 0)), "Unknown") -> Nordics
A42: ORD005990 | B42: C0261 | C42: 45231 | D42: =PROPER(orders[[#This Row],[order_priority]]) -> Standard | E42: Standard | F42: =IFERROR(INDEX(customers[country], MATCH(orders[[#This Row],[customer_id]], customers[customer_id], 0)), "Unmapped") -> Sweden | G42: =IFERROR(INDEX(Region_Map[Region], MATCH(orders[[#This Row],[Customer_Country]], Region_Map[Country], 0)), "Unknown") -> Nordics
A43: ORD001146 | B43: C0090 | C43: 45316 | D43: =PROPER(orders[[#This Row],[order_priority]]) -> Standard | E43: Standard | F43: =IFERROR(INDEX(customers[country], MATCH(orders[[#This Row],[customer_id]], customers[customer_id], 0)), "Unmapped") -> Norway | G43: =IFERROR(INDEX(Region_Map[Region], MATCH(orders[[#This Row],[Customer_Country]], Region_Map[Country], 0)), "Unknown") -> Nordics
A44: ORD000214 | B44: C0079 | C44: 45372 | D44: =PROPER(orders[[#This Row],[order_priority]]) -> Standard | E44: Standard | F44: =IFERROR(INDEX(customers[country], MATCH(orders[[#This Row],[customer_id]], customers[customer_id], 0)), "Unmapped") -> Lithuania | G44: =IFERROR(INDEX(Region_Map[Region], MATCH(orders[[#This Row],[Customer_Country]], Region_Map[Country], 0)), "Unknown") -> Baltics
A45: ORD005496 | B45: C0003 | C45: 45043 | D45: =PROPER(orders[[#This Row],[order_priority]]) -> Express | E45: Express | F45: =IFERROR(INDEX(customers[country], MATCH(orders[[#This Row],[customer_id]], customers[customer_id], 0)), "Unmapped") -> Estonia | G45: =IFERROR(INDEX(Region_Map[Region], MATCH(orders[[#This Row],[Customer_Country]], Region_Map[Country], 0)), "Unknown") -> Baltics
A46: ORD001692 | B46: C0059 | C46: 45317 | D46: =PROPER(orders[[#This Row],[order_priority]]) -> Standard | E46: Standard | F46: =IFERROR(INDEX(customers[country], MATCH(orders[[#This Row],[customer_id]], customers[customer_id], 0)), "Unmapped") -> Estonia | G46: =IFERROR(INDEX(Region_Map[Region], MATCH(orders[[#This Row],[Customer_Country]], Region_Map[Country], 0)), "Unknown") -> Baltics
...

Sheet Data_Quality_Audit.
A1: Table | B1: Field | C1: Issue | D1: Count | E1: Formular used
A2: Raw_Order | B2: Customer_ID | C2: Blanks | D2: =COUNTBLANK(orders[customer_id]) -> 38 | E2: COUNTBLANK
A3: Raw_Shipment | B3: Carrier | C3: Blanks | D3: =COUNTBLANK(Raw_shipments!C2:C6376) -> 188 | E3: COUNTBLANK
A4: Raw_Shipment | B4: actual_delivery_date | C4: Blanks | D4: =COUNTBLANK(shipments[actual_delivery_date]) -> 969 | E4: COUNTBLANK | J4: Country | K4: Region
A5: Raw_Shipment | B5: Shiping_cost_eur | C5: Blanks | D5: =COUNTBLANK(shipments[shipping_cost_eur]) -> 126 | E5: COUNTBLANK | J5: Sweden | K5: Nordics
A6: Raw_Order | B6: Region | C6: Blank | D6: =COUNTBLANK(orders[region]) -> 6025 | E6: COUNTBLANK | J6: Norway | K6: Nordics
A7: Raw_Order | B7: order_priority | C7: Inconsistent Casing (STANDARD) | D7: {=SUMPRODUCT(1 * EXACT(Raw_orders!E:E, "STANDARD"))} -> 95 | E7: SUMPRODUCT, EXACT | F7: Inconsistent casing occurs across other colums too in diffrent tables and fileds | J7: Denmark | K7: Nordics
A8: Raw_Order | B8: order_priority | C8: Inconsistent Casing (Standard) | D8: {=SUMPRODUCT(1 * EXACT(Raw_orders!E:E, "Standard"))} -> 1293 | E8: SUMPRODUCT, EXACT | J8: Finland | K8: Nordics
A9: Raw_Order | B9: order_priority | C9: Inconsistent Casing (standard) | D9: {=SUMPRODUCT(1 * EXACT(Raw_orders!E:E, "standard"))} -> 94 | E9: SUMPRODUCT, EXACT | J9: Latvia | K9: Baltics
A10: Raw_Shipment | B10: Delivery_status | C10: Inconsistent Casing (DELIVERED) | D10: {=SUMPRODUCT(1*EXACT(shipments[delivery_status], "DELIVERED"))} -> 1764 | E10: SUMPRODUCT, EXACT | J10: Estonia | K10: Baltics
A11: Raw_Shipment | B11: Delivery_status | C11: Inconsistent Casing(Delivered) | D11: {=SUMPRODUCT(1*EXACT(shipments[delivery_status], "Delivered"))} -> 1844 | E11: SUMPRODUCT, EXACT | J11: Lithuania | K11: Baltics
A12: Raw_Shipment | B12: Delivery_status | C12: Inconsistent Casing(delivered) | D12: {=SUMPRODUCT(1*EXACT(shipments[delivery_status], "delivered"))} -> 1798 | E12: SUMPRODUCT, EXACT | J12: Poland | K12: Central Europe
J13: Germany | K13: Central Europe
J14: Netherlands | K14: Central Europe
E16: =COUNTIF(Raw_shipments!J2:J6376,"Delivered") -> 5406
E17: =COUNTIF(Raw_orders!G:G, "Nordics") -> 2006
E18: =COUNTIF(shipments[Delivery_Performance], "Late") -> 3429
E19: =COUNTIF(shipments[Delivery_Performance], "On Time") -> 1977

Sheet Dashboard
B1: On-Time Delivery Performance & Logistics Cost
B2: Total Delivered Orders | D2: Overall On-Time Rate | F2: Total Shipping Spend
B4: =COUNTIF(shipments[Cleaned_delivery_status], "Delivered") -> 5406 | D4: =COUNTIFS(shipments[Cleaned_delivery_status], "Delivered", shipments[Delivery_Performance], "On Time") / COUNTIF(shipments[Cleaned_delivery_status], "Delivered") -> 0.36570477 | F4: =SUM(Raw_shipments!G:G) -> 217738.12
